#!/usr/bin/env python
# -*- coding: utf-8 -*-

# write a correct test!
import unittest

import pygimli as pg


class TestIterBug(unittest.TestCase):

    def test_MissingRefCounter(self):
        """ """
        a = pg.Vector(10, 1)

        # das geht schief wegen fehlendem referenzcounter. der Iter nutzt das
        # temporaere Object a(0,9) das nicht weiter gezaehlt wird
        # ich glaub unsere pygimli objecte brauchen einen refcounter
        # wenn sie von py aus generiert werden
        # print((a(0, 9).beginPyIter()[0], "!=", a[0]))
        # this might goes wrong but we cannot test it
        # self.assertNotEqual(a(0, 9).beginPyIter()[0], a[0])

        # das geht weil wir einen eigenen iter definieren der die referenz haellt
        # see: class VectorIter: in pygimli.__init__.py
        i = 0
        for ai in a[0:9]:
            self.assertEqual(ai, a[i])
            i = i + 1


if __name__ == "__main__":

    unittest.main()
